[TOC]
# 异常处理

### 1. 异常的分类

Java 中的所有异常都继承自 `java.lang.Throwable` 类。`Throwable` 又分为两大子类：

1.  **`Error` (错误)：**
    * 代表了程序中**非常严重**的问题，通常是 JVM 内部错误或资源耗尽等，这些问题超出了应用程序的控制和处理能力。
    * 例如：`OutOfMemoryError` (内存溢出)、`StackOverflowError` (栈溢出)。
    * **特点：** 绝大多数情况下，应用程序不应该尝试捕获或处理 `Error`。它们通常指示着需要修复底层系统或 JVM 配置的问题。

2.  **`Exception` (异常)：**
    * 代表了程序中可以**预见和处理**的问题。这些异常通常是由应用程序本身或外部环境引起的，开发者可以通过代码进行捕获和处理，使程序能够继续运行或优雅地终止。
    

### 2. 异常处理机制
#### 抛出异常
**程序出现异常，就立即创建一个相应的异常对象，并将其作为参数抛给处理该异常的代码块。**
1. 1 ==标准异常==，则抛出异常的工作就由系统自动完成。
2. ==用户自定义的异常==，就需要程序==创建异常类对象==，并借助throw语句将其==抛出==。


Java 提供了 `try-catch-finally` 语句块来处理异常：

* **`try` 块：** 包含可能会抛出异常的代码。
* **`catch` 块：** 用于捕获并处理 `try` 块中抛出的特定类型的异常。一个 `try` 块可以跟多个 `catch` 块，以处理不同类型的异常（从子类异常到父类异常的顺序）。
* **`finally` 块：** 无论 `try` 块中的代码是否发生异常，`finally` 块中的代码都会被执行。它通常用于释放资源（如关闭文件、数据库连接等），确保资源在任何情况下都能被清理。

**基本语法：**

```java
try {
    // 可能会抛出异常的代码
} catch (ExceptionType1 e1) {
    // 处理 ExceptionType1 类型的异常
} catch (ExceptionType2 e2) {
    // 处理 ExceptionType2 类型的异常
} finally {
    // 无论是否发生异常，都会执行的代码
    // 通常用于资源清理
}

public class TestTryCatch{
    public static void main(String[] args){
        int i=1;
        int j=0;
        try{
            System.out.println(“try block entered”);
　　　 System.out.println(i/j);  //产生ArithmeticException异常
　　     System.out.println(“Ending try block”);
            ｝catch(ArithmeticException e){
                  System.out.println(“Arithmetic Exception caugth”);
                }
         System.out.println(“After try block”);
       }
}   


public class TestTryCatch2{
  public static void main(String[] args){
    int i=3;
    for(int j=1;j>=-1;j--){
        try{
            System.out.println("try block entered");
	System.out.println(i/j);  
	System.out.println("Ending try block");
	}
           catch(ArithmeticException e){
	         System.out.println("Arithmetic Exception caugth");
                }
            finally{
	         System.out.println("finally block is executed ");
                }
        System.out.println("After try block");
       }
   }
}   

```
**Notice:**
1. 在catch语句中，通常是打印异常和与该异常相关的信息：异常名称、产生异常的方法名等。
2. 2应注意各catch块的次序：异常子类的catch块放在异常父类的catch块前面。否则会出现编译错误。

#### 处理异常
1.　在产生异常的方法中处理异常
2.　重新抛出异常给外层处理。(异常的嵌套处理)
```java
public class TestException{
  public static void main(String[] args){
       try {
	     try{
		        int i=1/0;
	         }catch(ArrayIndexOutOfBoundsException e){
		     System.out.println("error1"+e);
	          } 
	    }catch(ArithmeticException e){
	          System.out.println("error2 "+e);
	  }
   }
}
```
```java
public class  TestMethodException{
  public void a() throws Exception{ 	
     throw new Exception();      
  }	
   public static void main(String[] args){
     TestMethodException t1=new TestMethodException();
	 try{
		 t1.a();
	      }catch(Exception e){ 
		   System.out.println("Exception error");
	      }
	 }
}
```


**`throws` 关键字：**

当一个方法可能会抛出检查性异常，但你不想在该方法内部处理它时，可以在方法签名中使用 `throws` 关键字来声明该方法可能抛出的异常。这样，调用这个方法的代码就必须处理这个异常。

```java
public void readFile(String filePath) throws FileNotFoundException, IOException {
    // ... 文件读取操作，可能会抛出这两种异常，这是一个公共方法
}

// 调用者需要处理：
public static void main(String[] args) {
    MyClass obj = new MyClass();
    try {
        obj.readFile("path/to/file.txt");
    } catch (FileNotFoundException e) {
        System.err.println("文件未找到：" + e.getMessage());
    } catch (IOException e) {
        System.err.println("文件读取错误：" + e.getMessage());
    }
}


```
### 用户自定义异常：Throwable类的子类
　　　==建议用户自定义异常为Exception类的子类==
基本格式：
```java
class  TestException extends Exception{
      TestException(){
         super();
        }
      TestException(String s){
         super(s);
       }
  }
```
